<!--
  Franka Emika Panda 7-DOF robot arm with parallel-jaw gripper.
  Simplified MJCF model for SimVerse simulation.
  Based on publicly available Panda specifications.
-->
<mujoco model="panda">
  <compiler angle="radian" meshdir="." autolimits="true"/>

  <option timestep="0.002" gravity="0 0 -9.81" integrator="implicit"/>

  <default>
    <joint damping="1.0" armature="0.1"/>
    <geom condim="4" friction="1 0.5 0.01" solref="0.02 1"/>
    <position kp="100" kv="20"/>
    <default class="visual">
      <geom group="1" contype="0" conaffinity="0"/>
    </default>
    <default class="collision">
      <geom group="2"/>
    </default>
  </default>

  <asset>
    <material name="metal" rgba="0.7 0.7 0.7 1" specular="0.8" shininess="0.8"/>
    <material name="dark_metal" rgba="0.3 0.3 0.3 1" specular="0.6" shininess="0.6"/>
    <material name="gripper_mat" rgba="0.5 0.5 0.5 1"/>
  </asset>

  <worldbody>
    <body name="panda_link0" pos="0 0 0">
      <geom type="cylinder" size="0.06 0.05" pos="0 0 0.025" material="dark_metal" class="visual"/>
      <geom type="cylinder" size="0.06 0.05" pos="0 0 0.025" class="collision"/>

      <body name="panda_link1" pos="0 0 0.333">
        <joint name="joint1" type="hinge" axis="0 0 1" range="-2.8973 2.8973" damping="5.0"/>
        <geom type="capsule" fromto="0 0 0 0 0 -0.15" size="0.06" material="metal" class="visual"/>
        <geom type="capsule" fromto="0 0 0 0 0 -0.15" size="0.06" class="collision"/>

        <body name="panda_link2" pos="0 0 0" quat="0.707107 -0.707107 0 0">
          <joint name="joint2" type="hinge" axis="0 0 1" range="-1.7628 1.7628" damping="5.0"/>
          <geom type="capsule" fromto="0 0 0 0 -0.316 0" size="0.06" material="metal" class="visual"/>
          <geom type="capsule" fromto="0 0 0 0 -0.316 0" size="0.06" class="collision"/>

          <body name="panda_link3" pos="0 -0.316 0" quat="0.707107 0.707107 0 0">
            <joint name="joint3" type="hinge" axis="0 0 1" range="-2.8973 2.8973" damping="5.0"/>
            <geom type="capsule" fromto="0 0 0 0.0825 0 0" size="0.05" material="metal" class="visual"/>
            <geom type="capsule" fromto="0 0 0 0.0825 0 0" size="0.05" class="collision"/>

            <body name="panda_link4" pos="0.0825 0 0" quat="0.707107 0.707107 0 0">
              <joint name="joint4" type="hinge" axis="0 0 1" range="-3.0718 -0.0698" damping="5.0"/>
              <geom type="capsule" fromto="0 0 0 -0.0825 0.384 0" size="0.05" material="metal" class="visual"/>
              <geom type="capsule" fromto="0 0 0 -0.0825 0.384 0" size="0.05" class="collision"/>

              <body name="panda_link5" pos="-0.0825 0.384 0" quat="0.707107 -0.707107 0 0">
                <joint name="joint5" type="hinge" axis="0 0 1" range="-2.8973 2.8973" damping="3.0"/>
                <geom type="capsule" fromto="0 0 0 0 0 -0.1" size="0.04" material="dark_metal" class="visual"/>
                <geom type="capsule" fromto="0 0 0 0 0 -0.1" size="0.04" class="collision"/>

                <body name="panda_link6" pos="0 0 0" quat="0.707107 0.707107 0 0">
                  <joint name="joint6" type="hinge" axis="0 0 1" range="-0.0175 3.7525" damping="3.0"/>
                  <geom type="capsule" fromto="0 0 0 0.088 0 0" size="0.04" material="metal" class="visual"/>
                  <geom type="capsule" fromto="0 0 0 0.088 0 0" size="0.04" class="collision"/>

                  <body name="panda_link7" pos="0.088 0 0" quat="0.707107 0.707107 0 0">
                    <joint name="joint7" type="hinge" axis="0 0 1" range="-2.8973 2.8973" damping="1.0"/>
                    <geom type="cylinder" size="0.04 0.02" pos="0 0 0.05" material="dark_metal" class="visual"/>
                    <geom type="cylinder" size="0.04 0.02" pos="0 0 0.05" class="collision"/>

                    <site name="end_effector" pos="0 0 0.1034" size="0.01" rgba="1 0 0 1"/>

                    <!-- Gripper -->
                    <body name="panda_hand" pos="0 0 0.1034" quat="0.924 0 0 -0.383">
                      <geom type="box" size="0.015 0.04 0.03" pos="0 0 0.04" material="gripper_mat" class="visual"/>
                      <geom type="box" size="0.015 0.04 0.03" pos="0 0 0.04" class="collision"/>

                      <body name="panda_leftfinger" pos="0 0 0.0584">
                        <joint name="finger_joint1" type="slide" axis="0 1 0" range="0 0.04" damping="10"/>
                        <geom type="box" size="0.01 0.005 0.03" pos="0 0.015 0.02" material="gripper_mat" class="visual"/>
                        <geom type="box" size="0.01 0.005 0.03" pos="0 0.015 0.02" class="collision"/>
                      </body>

                      <body name="panda_rightfinger" pos="0 0 0.0584">
                        <joint name="finger_joint2" type="slide" axis="0 -1 0" range="0 0.04" damping="10"/>
                        <geom type="box" size="0.01 0.005 0.03" pos="0 -0.015 0.02" material="gripper_mat" class="visual"/>
                        <geom type="box" size="0.01 0.005 0.03" pos="0 -0.015 0.02" class="collision"/>
                      </body>
                    </body>
                  </body>
                </body>
              </body>
            </body>
          </body>
        </body>
      </body>
    </body>
  </worldbody>

  <actuator>
    <position name="actuator1" joint="joint1" kp="4500"/>
    <position name="actuator2" joint="joint2" kp="4500"/>
    <position name="actuator3" joint="joint3" kp="3500"/>
    <position name="actuator4" joint="joint4" kp="3500"/>
    <position name="actuator5" joint="joint5" kp="2000"/>
    <position name="actuator6" joint="joint6" kp="2000"/>
    <position name="actuator7" joint="joint7" kp="2000"/>
    <position name="actuator_finger1" joint="finger_joint1" kp="1000"/>
    <position name="actuator_finger2" joint="finger_joint2" kp="1000"/>
  </actuator>

  <sensor>
    <jointpos name="joint1_pos" joint="joint1"/>
    <jointpos name="joint2_pos" joint="joint2"/>
    <jointpos name="joint3_pos" joint="joint3"/>
    <jointpos name="joint4_pos" joint="joint4"/>
    <jointpos name="joint5_pos" joint="joint5"/>
    <jointpos name="joint6_pos" joint="joint6"/>
    <jointpos name="joint7_pos" joint="joint7"/>
    <jointvel name="joint1_vel" joint="joint1"/>
    <jointvel name="joint2_vel" joint="joint2"/>
    <jointvel name="joint3_vel" joint="joint3"/>
    <jointvel name="joint4_vel" joint="joint4"/>
    <jointvel name="joint5_vel" joint="joint5"/>
    <jointvel name="joint6_vel" joint="joint6"/>
    <jointvel name="joint7_vel" joint="joint7"/>
  </sensor>
</mujoco>
